[2021-12-13 13:57:53,452] {taskinstance.py:851} INFO - Dependencies all met for <TaskInstance: cleansing_dag.cleanse 2021-12-12T13:57:29.824654+00:00 [queued]>
[2021-12-13 13:57:53,465] {taskinstance.py:851} INFO - Dependencies all met for <TaskInstance: cleansing_dag.cleanse 2021-12-12T13:57:29.824654+00:00 [queued]>
[2021-12-13 13:57:53,466] {taskinstance.py:1042} INFO - 
--------------------------------------------------------------------------------
[2021-12-13 13:57:53,466] {taskinstance.py:1043} INFO - Starting attempt 1 of 2
[2021-12-13 13:57:53,466] {taskinstance.py:1044} INFO - 
--------------------------------------------------------------------------------
[2021-12-13 13:57:53,480] {taskinstance.py:1063} INFO - Executing <Task(PythonOperator): cleanse> on 2021-12-12T13:57:29.824654+00:00
[2021-12-13 13:57:53,484] {standard_task_runner.py:52} INFO - Started process 55 to run task
[2021-12-13 13:57:53,486] {standard_task_runner.py:76} INFO - Running: ['airflow', 'tasks', 'run', 'cleansing_dag', 'cleanse', '2021-12-12T13:57:29.824654+00:00', '--job-id', '2', '--pool', 'default_pool', '--raw', '--subdir', 'DAGS_FOLDER/kym_cleansing.py', '--cfg-path', '/tmp/tmp1mwjcj0w', '--error-file', '/tmp/tmp0nf87frr']
[2021-12-13 13:57:53,488] {standard_task_runner.py:77} INFO - Job 2: Subtask cleanse
[2021-12-13 13:57:53,523] {logging_mixin.py:104} INFO - Running <TaskInstance: cleansing_dag.cleanse 2021-12-12T13:57:29.824654+00:00 [running]> on host f26117982067
[2021-12-13 13:57:53,567] {taskinstance.py:1257} INFO - Exporting the following env vars:
AIRFLOW_CTX_DAG_OWNER=airflow
AIRFLOW_CTX_DAG_ID=cleansing_dag
AIRFLOW_CTX_TASK_ID=cleanse
AIRFLOW_CTX_EXECUTION_DATE=2021-12-12T13:57:29.824654+00:00
AIRFLOW_CTX_DAG_RUN_ID=scheduled__2021-12-12T13:57:29.824654+00:00
[2021-12-13 13:57:57,026] {taskinstance.py:1455} ERROR - type object 'datetime.datetime' has no attribute 'fromisoformat'
Traceback (most recent call last):
  File "/home/airflow/.local/lib/python3.6/site-packages/airflow/models/taskinstance.py", line 1112, in _run_raw_task
    self._prepare_and_execute_task_with_callbacks(context, task)
  File "/home/airflow/.local/lib/python3.6/site-packages/airflow/models/taskinstance.py", line 1285, in _prepare_and_execute_task_with_callbacks
    result = self._execute_task(context, task_copy)
  File "/home/airflow/.local/lib/python3.6/site-packages/airflow/models/taskinstance.py", line 1315, in _execute_task
    result = task_copy.execute(context=context)
  File "/home/airflow/.local/lib/python3.6/site-packages/airflow/operators/python.py", line 117, in execute
    return_value = self.execute_callable()
  File "/home/airflow/.local/lib/python3.6/site-packages/airflow/operators/python.py", line 128, in execute_callable
    return self.python_callable(*self.op_args, **self.op_kwargs)
  File "/opt/airflow/dags/kym_cleansing.py", line 80, in cleanse
    if datetime.fromtimestamp(meme['last_update_source']) > datetime.fromisoformat(
AttributeError: type object 'datetime.datetime' has no attribute 'fromisoformat'
[2021-12-13 13:57:57,032] {taskinstance.py:1503} INFO - Marking task as UP_FOR_RETRY. dag_id=cleansing_dag, task_id=cleanse, execution_date=20211212T135729, start_date=20211213T135753, end_date=20211213T135757
[2021-12-13 13:57:57,076] {local_task_job.py:146} INFO - Task exited with return code 1
