[2021-12-29 12:21:29,104] {taskinstance.py:903} INFO - Dependencies all met for <TaskInstance: cleansing_dag.create_relational_db 2021-12-28T12:18:49.063800+00:00 [queued]>
[2021-12-29 12:21:29,120] {taskinstance.py:903} INFO - Dependencies all met for <TaskInstance: cleansing_dag.create_relational_db 2021-12-28T12:18:49.063800+00:00 [queued]>
[2021-12-29 12:21:29,121] {taskinstance.py:1094} INFO - 
--------------------------------------------------------------------------------
[2021-12-29 12:21:29,121] {taskinstance.py:1095} INFO - Starting attempt 1 of 2
[2021-12-29 12:21:29,121] {taskinstance.py:1096} INFO - 
--------------------------------------------------------------------------------
[2021-12-29 12:21:29,132] {taskinstance.py:1114} INFO - Executing <Task(PythonOperator): create_relational_db> on 2021-12-28T12:18:49.063800+00:00
[2021-12-29 12:21:29,136] {standard_task_runner.py:52} INFO - Started process 14047 to run task
[2021-12-29 12:21:29,139] {standard_task_runner.py:76} INFO - Running: ['***', 'tasks', 'run', 'cleansing_dag', 'create_relational_db', '2021-12-28T12:18:49.063800+00:00', '--job-id', '329', '--pool', 'default_pool', '--raw', '--subdir', 'DAGS_FOLDER/kym_cleansing.py', '--cfg-path', '/tmp/tmp85b2h3y3', '--error-file', '/tmp/tmpsd3f3a2n']
[2021-12-29 12:21:29,140] {standard_task_runner.py:77} INFO - Job 329: Subtask create_relational_db
[2021-12-29 12:21:29,178] {logging_mixin.py:109} INFO - Running <TaskInstance: cleansing_dag.create_relational_db 2021-12-28T12:18:49.063800+00:00 [running]> on host 9b1c98289e99
[2021-12-29 12:21:29,225] {taskinstance.py:1251} INFO - Exporting the following env vars:
AIRFLOW_CTX_DAG_OWNER=***
AIRFLOW_CTX_DAG_ID=cleansing_dag
AIRFLOW_CTX_TASK_ID=create_relational_db
AIRFLOW_CTX_EXECUTION_DATE=2021-12-28T12:18:49.063800+00:00
AIRFLOW_CTX_DAG_RUN_ID=scheduled__2021-12-28T12:18:49.063800+00:00
[2021-12-29 12:21:29,318] {logging_mixin.py:109} WARNING - /opt/***/dags/kym_cleansing.py:231 SettingWithCopyWarning: 
A value is trying to be set on a copy of a slice from a DataFrame.
Try using .loc[row_indexer,col_indexer] = value instead

See the caveats in the documentation: https://pandas.pydata.org/pandas-docs/stable/user_guide/indexing.html#returning-a-view-versus-a-copy
[2021-12-29 12:21:29,320] {logging_mixin.py:109} WARNING - /opt/***/dags/kym_cleansing.py:232 SettingWithCopyWarning: 
A value is trying to be set on a copy of a slice from a DataFrame.
Try using .loc[row_indexer,col_indexer] = value instead

See the caveats in the documentation: https://pandas.pydata.org/pandas-docs/stable/user_guide/indexing.html#returning-a-view-versus-a-copy
[2021-12-29 12:21:29,326] {logging_mixin.py:109} WARNING - /opt/***/dags/kym_cleansing.py:235 SettingWithCopyWarning: 
A value is trying to be set on a copy of a slice from a DataFrame.
Try using .loc[row_indexer,col_indexer] = value instead

See the caveats in the documentation: https://pandas.pydata.org/pandas-docs/stable/user_guide/indexing.html#returning-a-view-versus-a-copy
[2021-12-29 12:21:29,513] {taskinstance.py:1462} ERROR - Task failed with exception
Traceback (most recent call last):
  File "/home/airflow/.local/lib/python3.8/site-packages/airflow/models/taskinstance.py", line 1164, in _run_raw_task
    self._prepare_and_execute_task_with_callbacks(context, task)
  File "/home/airflow/.local/lib/python3.8/site-packages/airflow/models/taskinstance.py", line 1282, in _prepare_and_execute_task_with_callbacks
    result = self._execute_task(context, task_copy)
  File "/home/airflow/.local/lib/python3.8/site-packages/airflow/models/taskinstance.py", line 1312, in _execute_task
    result = task_copy.execute(context=context)
  File "/home/airflow/.local/lib/python3.8/site-packages/airflow/operators/python.py", line 150, in execute
    return_value = self.execute_callable()
  File "/home/airflow/.local/lib/python3.8/site-packages/airflow/operators/python.py", line 161, in execute_callable
    return self.python_callable(*self.op_args, **self.op_kwargs)
  File "/opt/airflow/dags/kym_cleansing.py", line 292, in create_relational_db
    date_dimension = date_dimension_maker(fact_table)
  File "/opt/airflow/dags/kym_cleansing.py", line 257, in date_dimension_maker
    months = [datetime.strptime(str(x), "%m").strftime("%B") for x in date_dimension["Month"][:len(date_dimension) - 1]]
  File "/opt/airflow/dags/kym_cleansing.py", line 257, in <listcomp>
    months = [datetime.strptime(str(x), "%m").strftime("%B") for x in date_dimension["Month"][:len(date_dimension) - 1]]
  File "/usr/local/lib/python3.8/_strptime.py", line 568, in _strptime_datetime
    tt, fraction, gmtoff_fraction = _strptime(data_string, format)
  File "/usr/local/lib/python3.8/_strptime.py", line 349, in _strptime
    raise ValueError("time data %r does not match format %r" %
ValueError: time data 'nan' does not match format '%m'
[2021-12-29 12:21:29,520] {taskinstance.py:1505} INFO - Marking task as UP_FOR_RETRY. dag_id=cleansing_dag, task_id=create_relational_db, execution_date=20211228T121849, start_date=20211229T122129, end_date=20211229T122129
[2021-12-29 12:21:29,553] {local_task_job.py:151} INFO - Task exited with return code 1
