[2021-12-29 13:02:02,683] {taskinstance.py:903} INFO - Dependencies all met for <TaskInstance: cleansing_dag.create_additional_analysis_table_query 2021-12-28T12:59:02.489473+00:00 [queued]>
[2021-12-29 13:02:02,704] {taskinstance.py:903} INFO - Dependencies all met for <TaskInstance: cleansing_dag.create_additional_analysis_table_query 2021-12-28T12:59:02.489473+00:00 [queued]>
[2021-12-29 13:02:02,705] {taskinstance.py:1094} INFO - 
--------------------------------------------------------------------------------
[2021-12-29 13:02:02,706] {taskinstance.py:1095} INFO - Starting attempt 1 of 2
[2021-12-29 13:02:02,706] {taskinstance.py:1096} INFO - 
--------------------------------------------------------------------------------
[2021-12-29 13:02:02,721] {taskinstance.py:1114} INFO - Executing <Task(PythonOperator): create_additional_analysis_table_query> on 2021-12-28T12:59:02.489473+00:00
[2021-12-29 13:02:02,727] {standard_task_runner.py:52} INFO - Started process 9135 to run task
[2021-12-29 13:02:02,730] {standard_task_runner.py:76} INFO - Running: ['***', 'tasks', 'run', 'cleansing_dag', 'create_additional_analysis_table_query', '2021-12-28T12:59:02.489473+00:00', '--job-id', '362', '--pool', 'default_pool', '--raw', '--subdir', 'DAGS_FOLDER/kym_cleansing.py', '--cfg-path', '/tmp/tmpnfrg050s', '--error-file', '/tmp/tmpoxh7va1s']
[2021-12-29 13:02:02,731] {standard_task_runner.py:77} INFO - Job 362: Subtask create_additional_analysis_table_query
[2021-12-29 13:02:02,772] {logging_mixin.py:109} INFO - Running <TaskInstance: cleansing_dag.create_additional_analysis_table_query 2021-12-28T12:59:02.489473+00:00 [running]> on host 34521d0e1651
[2021-12-29 13:02:02,833] {taskinstance.py:1251} INFO - Exporting the following env vars:
AIRFLOW_CTX_DAG_OWNER=***
AIRFLOW_CTX_DAG_ID=cleansing_dag
AIRFLOW_CTX_TASK_ID=create_additional_analysis_table_query
AIRFLOW_CTX_EXECUTION_DATE=2021-12-28T12:59:02.489473+00:00
AIRFLOW_CTX_DAG_RUN_ID=scheduled__2021-12-28T12:59:02.489473+00:00
[2021-12-29 13:02:02,941] {taskinstance.py:1462} ERROR - Task failed with exception
Traceback (most recent call last):
  File "/home/airflow/.local/lib/python3.8/site-packages/airflow/models/taskinstance.py", line 1164, in _run_raw_task
    self._prepare_and_execute_task_with_callbacks(context, task)
  File "/home/airflow/.local/lib/python3.8/site-packages/airflow/models/taskinstance.py", line 1282, in _prepare_and_execute_task_with_callbacks
    result = self._execute_task(context, task_copy)
  File "/home/airflow/.local/lib/python3.8/site-packages/airflow/models/taskinstance.py", line 1312, in _execute_task
    result = task_copy.execute(context=context)
  File "/home/airflow/.local/lib/python3.8/site-packages/airflow/operators/python.py", line 150, in execute
    return_value = self.execute_callable()
  File "/home/airflow/.local/lib/python3.8/site-packages/airflow/operators/python.py", line 161, in execute_callable
    return self.python_callable(*self.op_args, **self.op_kwargs)
  File "/opt/airflow/dags/kym_cleansing.py", line 485, in create_additional_analysis_table_query
    "INSERT INTO additional_analysis_table VALUES ("
NameError: name 'text' is not defined
[2021-12-29 13:02:02,946] {taskinstance.py:1505} INFO - Marking task as UP_FOR_RETRY. dag_id=cleansing_dag, task_id=create_additional_analysis_table_query, execution_date=20211228T125902, start_date=20211229T130202, end_date=20211229T130202
[2021-12-29 13:02:02,983] {local_task_job.py:151} INFO - Task exited with return code 1
