[2021-12-28 14:13:03,686] {taskinstance.py:851} INFO - Dependencies all met for <TaskInstance: cleansing_dag.insert_origin_dimension_query 2021-12-27T10:09:03.182058+00:00 [queued]>
[2021-12-28 14:13:03,707] {taskinstance.py:851} INFO - Dependencies all met for <TaskInstance: cleansing_dag.insert_origin_dimension_query 2021-12-27T10:09:03.182058+00:00 [queued]>
[2021-12-28 14:13:03,708] {taskinstance.py:1042} INFO - 
--------------------------------------------------------------------------------
[2021-12-28 14:13:03,708] {taskinstance.py:1043} INFO - Starting attempt 1 of 2
[2021-12-28 14:13:03,708] {taskinstance.py:1044} INFO - 
--------------------------------------------------------------------------------
[2021-12-28 14:13:03,720] {taskinstance.py:1063} INFO - Executing <Task(PostgresOperator): insert_origin_dimension_query> on 2021-12-27T10:09:03.182058+00:00
[2021-12-28 14:13:03,727] {standard_task_runner.py:52} INFO - Started process 65 to run task
[2021-12-28 14:13:03,732] {standard_task_runner.py:76} INFO - Running: ['airflow', 'tasks', 'run', 'cleansing_dag', 'insert_origin_dimension_query', '2021-12-27T10:09:03.182058+00:00', '--job-id', '66', '--pool', 'default_pool', '--raw', '--subdir', 'DAGS_FOLDER/kym_cleansing.py', '--cfg-path', '/tmp/tmp6my16v2z', '--error-file', '/tmp/tmpvt1e02yi']
[2021-12-28 14:13:03,733] {standard_task_runner.py:77} INFO - Job 66: Subtask insert_origin_dimension_query
[2021-12-28 14:13:03,773] {logging_mixin.py:104} INFO - Running <TaskInstance: cleansing_dag.insert_origin_dimension_query 2021-12-27T10:09:03.182058+00:00 [running]> on host 78fdbf5e507e
[2021-12-28 14:13:03,790] {taskinstance.py:1455} ERROR - origin_dimension_inserts.sql
Traceback (most recent call last):
  File "/home/airflow/.local/lib/python3.8/site-packages/airflow/models/taskinstance.py", line 1112, in _run_raw_task
    self._prepare_and_execute_task_with_callbacks(context, task)
  File "/home/airflow/.local/lib/python3.8/site-packages/airflow/models/taskinstance.py", line 1249, in _prepare_and_execute_task_with_callbacks
    self.render_templates(context=context)
  File "/home/airflow/.local/lib/python3.8/site-packages/airflow/models/taskinstance.py", line 1750, in render_templates
    self.task.render_template_fields(context)
  File "/home/airflow/.local/lib/python3.8/site-packages/airflow/models/baseoperator.py", line 859, in render_template_fields
    self._do_render_template_fields(self, self.template_fields, context, jinja_env, set())
  File "/home/airflow/.local/lib/python3.8/site-packages/airflow/models/baseoperator.py", line 872, in _do_render_template_fields
    rendered_content = self.render_template(content, context, jinja_env, seen_oids)
  File "/home/airflow/.local/lib/python3.8/site-packages/airflow/models/baseoperator.py", line 907, in render_template
    return jinja_env.get_template(content).render(**context)
  File "/home/airflow/.local/lib/python3.8/site-packages/jinja2/environment.py", line 883, in get_template
    return self._load_template(name, self.make_globals(globals))
  File "/home/airflow/.local/lib/python3.8/site-packages/jinja2/environment.py", line 857, in _load_template
    template = self.loader.load(self, name, globals)
  File "/home/airflow/.local/lib/python3.8/site-packages/jinja2/loaders.py", line 115, in load
    source, filename, uptodate = self.get_source(environment, name)
  File "/home/airflow/.local/lib/python3.8/site-packages/jinja2/loaders.py", line 197, in get_source
    raise TemplateNotFound(template)
jinja2.exceptions.TemplateNotFound: origin_dimension_inserts.sql
[2021-12-28 14:13:03,792] {taskinstance.py:1496} INFO - Marking task as UP_FOR_RETRY. dag_id=cleansing_dag, task_id=insert_origin_dimension_query, execution_date=20211227T100903, start_date=20211228T141303, end_date=20211228T141303
[2021-12-28 14:13:03,823] {local_task_job.py:146} INFO - Task exited with return code 1
