[2021-12-29 12:13:41,935] {taskinstance.py:903} INFO - Dependencies all met for <TaskInstance: cleansing_dag.create_additional_analysis_table_query 2021-12-28T12:10:39.570058+00:00 [queued]>
[2021-12-29 12:13:41,955] {taskinstance.py:903} INFO - Dependencies all met for <TaskInstance: cleansing_dag.create_additional_analysis_table_query 2021-12-28T12:10:39.570058+00:00 [queued]>
[2021-12-29 12:13:41,956] {taskinstance.py:1094} INFO - 
--------------------------------------------------------------------------------
[2021-12-29 12:13:41,957] {taskinstance.py:1095} INFO - Starting attempt 1 of 2
[2021-12-29 12:13:41,957] {taskinstance.py:1096} INFO - 
--------------------------------------------------------------------------------
[2021-12-29 12:13:41,969] {taskinstance.py:1114} INFO - Executing <Task(PythonOperator): create_additional_analysis_table_query> on 2021-12-28T12:10:39.570058+00:00
[2021-12-29 12:13:41,974] {standard_task_runner.py:52} INFO - Started process 7024 to run task
[2021-12-29 12:13:41,978] {standard_task_runner.py:76} INFO - Running: ['***', 'tasks', 'run', 'cleansing_dag', 'create_additional_analysis_table_query', '2021-12-28T12:10:39.570058+00:00', '--job-id', '317', '--pool', 'default_pool', '--raw', '--subdir', 'DAGS_FOLDER/kym_cleansing.py', '--cfg-path', '/tmp/tmpzrgl3s0e', '--error-file', '/tmp/tmpod2hytx1']
[2021-12-29 12:13:41,979] {standard_task_runner.py:77} INFO - Job 317: Subtask create_additional_analysis_table_query
[2021-12-29 12:13:42,043] {logging_mixin.py:109} INFO - Running <TaskInstance: cleansing_dag.create_additional_analysis_table_query 2021-12-28T12:10:39.570058+00:00 [running]> on host 9b1c98289e99
[2021-12-29 12:13:42,112] {taskinstance.py:1251} INFO - Exporting the following env vars:
AIRFLOW_CTX_DAG_OWNER=***
AIRFLOW_CTX_DAG_ID=cleansing_dag
AIRFLOW_CTX_TASK_ID=create_additional_analysis_table_query
AIRFLOW_CTX_EXECUTION_DATE=2021-12-28T12:10:39.570058+00:00
AIRFLOW_CTX_DAG_RUN_ID=scheduled__2021-12-28T12:10:39.570058+00:00
[2021-12-29 12:13:42,256] {taskinstance.py:1462} ERROR - Task failed with exception
Traceback (most recent call last):
  File "/home/airflow/.local/lib/python3.8/site-packages/pandas/core/indexes/base.py", line 3361, in get_loc
    return self._engine.get_loc(casted_key)
  File "pandas/_libs/index.pyx", line 76, in pandas._libs.index.IndexEngine.get_loc
  File "pandas/_libs/index.pyx", line 108, in pandas._libs.index.IndexEngine.get_loc
  File "pandas/_libs/hashtable_class_helper.pxi", line 5198, in pandas._libs.hashtable.PyObjectHashTable.get_item
  File "pandas/_libs/hashtable_class_helper.pxi", line 5206, in pandas._libs.hashtable.PyObjectHashTable.get_item
KeyError: '@text'

The above exception was the direct cause of the following exception:

Traceback (most recent call last):
  File "/home/airflow/.local/lib/python3.8/site-packages/airflow/models/taskinstance.py", line 1164, in _run_raw_task
    self._prepare_and_execute_task_with_callbacks(context, task)
  File "/home/airflow/.local/lib/python3.8/site-packages/airflow/models/taskinstance.py", line 1282, in _prepare_and_execute_task_with_callbacks
    result = self._execute_task(context, task_copy)
  File "/home/airflow/.local/lib/python3.8/site-packages/airflow/models/taskinstance.py", line 1312, in _execute_task
    result = task_copy.execute(context=context)
  File "/home/airflow/.local/lib/python3.8/site-packages/airflow/operators/python.py", line 150, in execute
    return_value = self.execute_callable()
  File "/home/airflow/.local/lib/python3.8/site-packages/airflow/operators/python.py", line 161, in execute_callable
    return self.python_callable(*self.op_args, **self.op_kwargs)
  File "/opt/airflow/dags/kym_cleansing.py", line 480, in create_additional_analysis_table_query
    text = row['@text']
  File "/home/airflow/.local/lib/python3.8/site-packages/pandas/core/series.py", line 942, in __getitem__
    return self._get_value(key)
  File "/home/airflow/.local/lib/python3.8/site-packages/pandas/core/series.py", line 1051, in _get_value
    loc = self.index.get_loc(label)
  File "/home/airflow/.local/lib/python3.8/site-packages/pandas/core/indexes/base.py", line 3363, in get_loc
    raise KeyError(key) from err
KeyError: '@text'
[2021-12-29 12:13:42,274] {taskinstance.py:1505} INFO - Marking task as UP_FOR_RETRY. dag_id=cleansing_dag, task_id=create_additional_analysis_table_query, execution_date=20211228T121039, start_date=20211229T121341, end_date=20211229T121342
[2021-12-29 12:13:42,310] {local_task_job.py:151} INFO - Task exited with return code 1
