[2021-12-09 15:53:35,622] {taskinstance.py:851} INFO - Dependencies all met for <TaskInstance: cleansing_dag.cleanse 2021-12-09T15:53:34.637918+00:00 [queued]>
[2021-12-09 15:53:35,641] {taskinstance.py:851} INFO - Dependencies all met for <TaskInstance: cleansing_dag.cleanse 2021-12-09T15:53:34.637918+00:00 [queued]>
[2021-12-09 15:53:35,642] {taskinstance.py:1042} INFO - 
--------------------------------------------------------------------------------
[2021-12-09 15:53:35,643] {taskinstance.py:1043} INFO - Starting attempt 1 of 2
[2021-12-09 15:53:35,643] {taskinstance.py:1044} INFO - 
--------------------------------------------------------------------------------
[2021-12-09 15:53:35,654] {taskinstance.py:1063} INFO - Executing <Task(PythonOperator): cleanse> on 2021-12-09T15:53:34.637918+00:00
[2021-12-09 15:53:35,658] {standard_task_runner.py:52} INFO - Started process 120 to run task
[2021-12-09 15:53:35,661] {standard_task_runner.py:76} INFO - Running: ['airflow', 'tasks', 'run', 'cleansing_dag', 'cleanse', '2021-12-09T15:53:34.637918+00:00', '--job-id', '47', '--pool', 'default_pool', '--raw', '--subdir', 'DAGS_FOLDER/kym_cleansing.py', '--cfg-path', '/tmp/tmpag4jumct', '--error-file', '/tmp/tmpmujoj8j6']
[2021-12-09 15:53:35,663] {standard_task_runner.py:77} INFO - Job 47: Subtask cleanse
[2021-12-09 15:53:35,703] {logging_mixin.py:104} INFO - Running <TaskInstance: cleansing_dag.cleanse 2021-12-09T15:53:34.637918+00:00 [running]> on host 8ea24132e477
[2021-12-09 15:53:35,743] {taskinstance.py:1257} INFO - Exporting the following env vars:
AIRFLOW_CTX_DAG_OWNER=airflow
AIRFLOW_CTX_DAG_ID=cleansing_dag
AIRFLOW_CTX_TASK_ID=cleanse
AIRFLOW_CTX_EXECUTION_DATE=2021-12-09T15:53:34.637918+00:00
AIRFLOW_CTX_DAG_RUN_ID=manual__2021-12-09T15:53:34.637918+00:00
[2021-12-09 15:53:38,562] {taskinstance.py:1455} ERROR - module 'datetime' has no attribute 'fromtimestamp'
Traceback (most recent call last):
  File "/home/airflow/.local/lib/python3.6/site-packages/airflow/models/taskinstance.py", line 1112, in _run_raw_task
    self._prepare_and_execute_task_with_callbacks(context, task)
  File "/home/airflow/.local/lib/python3.6/site-packages/airflow/models/taskinstance.py", line 1285, in _prepare_and_execute_task_with_callbacks
    result = self._execute_task(context, task_copy)
  File "/home/airflow/.local/lib/python3.6/site-packages/airflow/models/taskinstance.py", line 1315, in _execute_task
    result = task_copy.execute(context=context)
  File "/home/airflow/.local/lib/python3.6/site-packages/airflow/operators/python.py", line 117, in execute
    return_value = self.execute_callable()
  File "/home/airflow/.local/lib/python3.6/site-packages/airflow/operators/python.py", line 128, in execute_callable
    return self.python_callable(*self.op_args, **self.op_kwargs)
  File "/opt/airflow/dags/kym_cleansing.py", line 91, in cleanse
    meme_dict['last_update_in_kym'] = datetime.fromtimestamp(meme['last_update_source']).strftime(
AttributeError: module 'datetime' has no attribute 'fromtimestamp'
[2021-12-09 15:53:38,568] {taskinstance.py:1503} INFO - Marking task as UP_FOR_RETRY. dag_id=cleansing_dag, task_id=cleanse, execution_date=20211209T155334, start_date=20211209T155335, end_date=20211209T155338
[2021-12-09 15:53:38,609] {local_task_job.py:146} INFO - Task exited with return code 1
