[2021-12-27 15:50:51,982] {taskinstance.py:851} INFO - Dependencies all met for <TaskInstance: cleansing_dag.postgres_load 2021-12-26T15:47:50.127847+00:00 [queued]>
[2021-12-27 15:50:52,001] {taskinstance.py:851} INFO - Dependencies all met for <TaskInstance: cleansing_dag.postgres_load 2021-12-26T15:47:50.127847+00:00 [queued]>
[2021-12-27 15:50:52,002] {taskinstance.py:1042} INFO - 
--------------------------------------------------------------------------------
[2021-12-27 15:50:52,002] {taskinstance.py:1043} INFO - Starting attempt 1 of 2
[2021-12-27 15:50:52,003] {taskinstance.py:1044} INFO - 
--------------------------------------------------------------------------------
[2021-12-27 15:50:52,018] {taskinstance.py:1063} INFO - Executing <Task(PythonOperator): postgres_load> on 2021-12-26T15:47:50.127847+00:00
[2021-12-27 15:50:52,024] {standard_task_runner.py:52} INFO - Started process 7109 to run task
[2021-12-27 15:50:52,027] {standard_task_runner.py:76} INFO - Running: ['airflow', 'tasks', 'run', 'cleansing_dag', 'postgres_load', '2021-12-26T15:47:50.127847+00:00', '--job-id', '51', '--pool', 'default_pool', '--raw', '--subdir', 'DAGS_FOLDER/kym_cleansing.py', '--cfg-path', '/tmp/tmpapef5i1s', '--error-file', '/tmp/tmpz_s0gpau']
[2021-12-27 15:50:52,029] {standard_task_runner.py:77} INFO - Job 51: Subtask postgres_load
[2021-12-27 15:50:52,074] {logging_mixin.py:104} INFO - Running <TaskInstance: cleansing_dag.postgres_load 2021-12-26T15:47:50.127847+00:00 [running]> on host d83a161471aa
[2021-12-27 15:50:52,116] {taskinstance.py:1255} INFO - Exporting the following env vars:
AIRFLOW_CTX_DAG_OWNER=airflow
AIRFLOW_CTX_DAG_ID=cleansing_dag
AIRFLOW_CTX_TASK_ID=postgres_load
AIRFLOW_CTX_EXECUTION_DATE=2021-12-26T15:47:50.127847+00:00
AIRFLOW_CTX_DAG_RUN_ID=scheduled__2021-12-26T15:47:50.127847+00:00
[2021-12-27 15:50:52,227] {logging_mixin.py:104} WARNING - /opt/airflow/dags/kym_cleansing.py:229 SettingWithCopyWarning: 
A value is trying to be set on a copy of a slice from a DataFrame.
Try using .loc[row_indexer,col_indexer] = value instead

See the caveats in the documentation: https://pandas.pydata.org/pandas-docs/stable/user_guide/indexing.html#returning-a-view-versus-a-copy
[2021-12-27 15:50:52,236] {logging_mixin.py:104} WARNING - /opt/airflow/dags/kym_cleansing.py:232 SettingWithCopyWarning: 
A value is trying to be set on a copy of a slice from a DataFrame.
Try using .loc[row_indexer,col_indexer] = value instead

See the caveats in the documentation: https://pandas.pydata.org/pandas-docs/stable/user_guide/indexing.html#returning-a-view-versus-a-copy
[2021-12-27 15:50:52,520] {taskinstance.py:1455} ERROR - could not connect to server: Connection refused
	Is the server running on host "127.0.0.1" and accepting
	TCP/IP connections on port 5432?
Traceback (most recent call last):
  File "/home/airflow/.local/lib/python3.8/site-packages/airflow/models/taskinstance.py", line 1112, in _run_raw_task
    self._prepare_and_execute_task_with_callbacks(context, task)
  File "/home/airflow/.local/lib/python3.8/site-packages/airflow/models/taskinstance.py", line 1285, in _prepare_and_execute_task_with_callbacks
    result = self._execute_task(context, task_copy)
  File "/home/airflow/.local/lib/python3.8/site-packages/airflow/models/taskinstance.py", line 1315, in _execute_task
    result = task_copy.execute(context=context)
  File "/home/airflow/.local/lib/python3.8/site-packages/airflow/operators/python.py", line 117, in execute
    return_value = self.execute_callable()
  File "/home/airflow/.local/lib/python3.8/site-packages/airflow/operators/python.py", line 128, in execute_callable
    return self.python_callable(*self.op_args, **self.op_kwargs)
  File "/opt/airflow/dags/kym_cleansing.py", line 291, in postgres_load
    conn = psycopg2.connect(
  File "/home/airflow/.local/lib/python3.8/site-packages/psycopg2/__init__.py", line 127, in connect
    conn = _connect(dsn, connection_factory=connection_factory, **kwasync)
psycopg2.OperationalError: could not connect to server: Connection refused
	Is the server running on host "127.0.0.1" and accepting
	TCP/IP connections on port 5432?

[2021-12-27 15:50:52,529] {taskinstance.py:1496} INFO - Marking task as UP_FOR_RETRY. dag_id=cleansing_dag, task_id=postgres_load, execution_date=20211226T154750, start_date=20211227T155051, end_date=20211227T155052
[2021-12-27 15:50:52,561] {local_task_job.py:146} INFO - Task exited with return code 1
