[2021-12-28 19:59:20,184] {taskinstance.py:903} INFO - Dependencies all met for <TaskInstance: cleansing_dag.insert_type_dimension_query 2021-12-27T19:56:23.170629+00:00 [queued]>
[2021-12-28 19:59:20,205] {taskinstance.py:903} INFO - Dependencies all met for <TaskInstance: cleansing_dag.insert_type_dimension_query 2021-12-27T19:56:23.170629+00:00 [queued]>
[2021-12-28 19:59:20,205] {taskinstance.py:1094} INFO - 
--------------------------------------------------------------------------------
[2021-12-28 19:59:20,206] {taskinstance.py:1095} INFO - Starting attempt 1 of 2
[2021-12-28 19:59:20,206] {taskinstance.py:1096} INFO - 
--------------------------------------------------------------------------------
[2021-12-28 19:59:20,217] {taskinstance.py:1114} INFO - Executing <Task(PostgresOperator): insert_type_dimension_query> on 2021-12-27T19:56:23.170629+00:00
[2021-12-28 19:59:20,223] {standard_task_runner.py:52} INFO - Started process 7051 to run task
[2021-12-28 19:59:20,227] {standard_task_runner.py:76} INFO - Running: ['***', 'tasks', 'run', 'cleansing_dag', 'insert_type_dimension_query', '2021-12-27T19:56:23.170629+00:00', '--job-id', '255', '--pool', 'default_pool', '--raw', '--subdir', 'DAGS_FOLDER/kym_cleansing.py', '--cfg-path', '/tmp/tmp3mlkx0zv', '--error-file', '/tmp/tmp9rbm1y_9']
[2021-12-28 19:59:20,228] {standard_task_runner.py:77} INFO - Job 255: Subtask insert_type_dimension_query
[2021-12-28 19:59:20,274] {logging_mixin.py:109} INFO - Running <TaskInstance: cleansing_dag.insert_type_dimension_query 2021-12-27T19:56:23.170629+00:00 [running]> on host 62c7f391d30e
[2021-12-28 19:59:20,329] {taskinstance.py:1251} INFO - Exporting the following env vars:
AIRFLOW_CTX_DAG_OWNER=***
AIRFLOW_CTX_DAG_ID=cleansing_dag
AIRFLOW_CTX_TASK_ID=insert_type_dimension_query
AIRFLOW_CTX_EXECUTION_DATE=2021-12-27T19:56:23.170629+00:00
AIRFLOW_CTX_DAG_RUN_ID=scheduled__2021-12-27T19:56:23.170629+00:00
[2021-12-28 19:59:20,330] {postgres.py:68} INFO - Executing: CREATE TABLE IF NOT EXISTS type_dimension (
type_id INT NOT NULL,
meme_type VARCHAR());
INSERT INTO type_dimension VALUES ('0', 'pop-culture-reference');
INSERT INTO type_dimension VALUES ('1', 'song');
INSERT INTO type_dimension VALUES ('2', 'viral-video');
INSERT INTO type_dimension VALUES ('3', 'dance');
INSERT INTO type_dimension VALUES ('4', 'No type');
INSERT INTO type_dimension VALUES ('5', 'catchphrase');
INSERT INTO type_dimension VALUES ('6', 'image-macro');
INSERT INTO type_dimension VALUES ('7', 'slang');
INSERT INTO type_dimension VALUES ('8', 'participatory-media');
INSERT INTO type_dimension VALUES ('9', 'shock-media');
INSERT INTO type_dimension VALUES ('10', 'visual-effect');
INSERT INTO type_dimension VALUES ('11', 'parody');
INSERT INTO type_dimension VALUES ('12', 'remix');
INSERT INTO type_dimension VALUES ('13', 'character');
INSERT INTO type_dimension VALUES ('14', 'hoax');
INSERT INTO type_dimension VALUES ('15', 'advertisement');
INSERT INTO type_dimension VALUES ('16', 'snowclone');
INSERT INTO type_dimension VALUES ('17', 'reaction');
INSERT INTO type_dimension VALUES ('18', 'copypasta');
INSERT INTO type_dimension VALUES ('19', 'social-game');
INSERT INTO type_dimension VALUES ('20', 'axiom');
INSERT INTO type_dimension VALUES ('21', 'optical-illusion');
INSERT INTO type_dimension VALUES ('22', 'photoshop');
INSERT INTO type_dimension VALUES ('23', 'emoticon');
INSERT INTO type_dimension VALUES ('24', 'animal');
INSERT INTO type_dimension VALUES ('25', 'creepypasta');
INSERT INTO type_dimension VALUES ('26', 'sound-effect');
INSERT INTO type_dimension VALUES ('27', 'lip-dub');
INSERT INTO type_dimension VALUES ('28', 'fan-labor');
INSERT INTO type_dimension VALUES ('29', 'fan-art');
INSERT INTO type_dimension VALUES ('30', 'conspiracy-theory');
INSERT INTO type_dimension VALUES ('31', 'viral-debate');
INSERT INTO type_dimension VALUES ('32', 'hashtag');
INSERT INTO type_dimension VALUES ('33', 'cliche');
[2021-12-28 19:59:20,339] {base.py:70} INFO - Using connection to: id: postgres_default. Host: localhost, Port: 5432, Schema: ***, Login: ***, Password: ***, extra: {}
[2021-12-28 19:59:20,340] {taskinstance.py:1462} ERROR - Task failed with exception
Traceback (most recent call last):
  File "/home/airflow/.local/lib/python3.8/site-packages/airflow/models/taskinstance.py", line 1164, in _run_raw_task
    self._prepare_and_execute_task_with_callbacks(context, task)
  File "/home/airflow/.local/lib/python3.8/site-packages/airflow/models/taskinstance.py", line 1282, in _prepare_and_execute_task_with_callbacks
    result = self._execute_task(context, task_copy)
  File "/home/airflow/.local/lib/python3.8/site-packages/airflow/models/taskinstance.py", line 1312, in _execute_task
    result = task_copy.execute(context=context)
  File "/home/airflow/.local/lib/python3.8/site-packages/airflow/providers/postgres/operators/postgres.py", line 70, in execute
    self.hook.run(self.sql, self.autocommit, parameters=self.parameters)
  File "/home/airflow/.local/lib/python3.8/site-packages/airflow/hooks/dbapi.py", line 177, in run
    with closing(self.get_conn()) as conn:
  File "/home/airflow/.local/lib/python3.8/site-packages/airflow/providers/postgres/hooks/postgres.py", line 115, in get_conn
    self.conn = psycopg2.connect(**conn_args)
  File "/home/airflow/.local/lib/python3.8/site-packages/psycopg2/__init__.py", line 122, in connect
    conn = _connect(dsn, connection_factory=connection_factory, **kwasync)
psycopg2.OperationalError: could not connect to server: Connection refused
	Is the server running on host "localhost" (127.0.0.1) and accepting
	TCP/IP connections on port 5432?
could not connect to server: Cannot assign requested address
	Is the server running on host "localhost" (::1) and accepting
	TCP/IP connections on port 5432?

[2021-12-28 19:59:20,343] {taskinstance.py:1505} INFO - Marking task as UP_FOR_RETRY. dag_id=cleansing_dag, task_id=insert_type_dimension_query, execution_date=20211227T195623, start_date=20211228T195920, end_date=20211228T195920
[2021-12-28 19:59:20,399] {local_task_job.py:151} INFO - Task exited with return code 1
