[2021-12-31 10:16:04,932] {taskinstance.py:903} INFO - Dependencies all met for <TaskInstance: main_dag.create_tables 2021-12-30T10:11:15.996335+00:00 [queued]>
[2021-12-31 10:16:04,944] {taskinstance.py:903} INFO - Dependencies all met for <TaskInstance: main_dag.create_tables 2021-12-30T10:11:15.996335+00:00 [queued]>
[2021-12-31 10:16:04,945] {taskinstance.py:1094} INFO - 
--------------------------------------------------------------------------------
[2021-12-31 10:16:04,945] {taskinstance.py:1095} INFO - Starting attempt 1 of 2
[2021-12-31 10:16:04,946] {taskinstance.py:1096} INFO - 
--------------------------------------------------------------------------------
[2021-12-31 10:16:04,961] {taskinstance.py:1114} INFO - Executing <Task(PythonOperator): create_tables> on 2021-12-30T10:11:15.996335+00:00
[2021-12-31 10:16:04,966] {standard_task_runner.py:52} INFO - Started process 13917 to run task
[2021-12-31 10:16:04,968] {standard_task_runner.py:76} INFO - Running: ['***', 'tasks', 'run', 'main_dag', 'create_tables', '2021-12-30T10:11:15.996335+00:00', '--job-id', '63', '--pool', 'default_pool', '--raw', '--subdir', 'DAGS_FOLDER/main_dag.py', '--cfg-path', '/tmp/tmpteyz52b4', '--error-file', '/tmp/tmpfm04s0ua']
[2021-12-31 10:16:04,969] {standard_task_runner.py:77} INFO - Job 63: Subtask create_tables
[2021-12-31 10:16:05,006] {logging_mixin.py:109} INFO - Running <TaskInstance: main_dag.create_tables 2021-12-30T10:11:15.996335+00:00 [running]> on host 71257c6b2a25
[2021-12-31 10:16:05,053] {taskinstance.py:1251} INFO - Exporting the following env vars:
AIRFLOW_CTX_DAG_OWNER=***
AIRFLOW_CTX_DAG_ID=main_dag
AIRFLOW_CTX_TASK_ID=create_tables
AIRFLOW_CTX_EXECUTION_DATE=2021-12-30T10:11:15.996335+00:00
AIRFLOW_CTX_DAG_RUN_ID=scheduled__2021-12-30T10:11:15.996335+00:00
[2021-12-31 10:16:05,165] {logging_mixin.py:109} WARNING - /opt/***/dags/main_dag.py:248 SettingWithCopyWarning: 
A value is trying to be set on a copy of a slice from a DataFrame.
Try using .loc[row_indexer,col_indexer] = value instead

See the caveats in the documentation: https://pandas.pydata.org/pandas-docs/stable/user_guide/indexing.html#returning-a-view-versus-a-copy
[2021-12-31 10:16:05,168] {logging_mixin.py:109} WARNING - /opt/***/dags/main_dag.py:249 SettingWithCopyWarning: 
A value is trying to be set on a copy of a slice from a DataFrame.
Try using .loc[row_indexer,col_indexer] = value instead

See the caveats in the documentation: https://pandas.pydata.org/pandas-docs/stable/user_guide/indexing.html#returning-a-view-versus-a-copy
[2021-12-31 10:16:05,175] {logging_mixin.py:109} WARNING - /opt/***/dags/main_dag.py:252 SettingWithCopyWarning: 
A value is trying to be set on a copy of a slice from a DataFrame.
Try using .loc[row_indexer,col_indexer] = value instead

See the caveats in the documentation: https://pandas.pydata.org/pandas-docs/stable/user_guide/indexing.html#returning-a-view-versus-a-copy
[2021-12-31 10:16:05,424] {taskinstance.py:1462} ERROR - Task failed with exception
Traceback (most recent call last):
  File "/home/airflow/.local/lib/python3.8/site-packages/airflow/models/taskinstance.py", line 1164, in _run_raw_task
    self._prepare_and_execute_task_with_callbacks(context, task)
  File "/home/airflow/.local/lib/python3.8/site-packages/airflow/models/taskinstance.py", line 1282, in _prepare_and_execute_task_with_callbacks
    result = self._execute_task(context, task_copy)
  File "/home/airflow/.local/lib/python3.8/site-packages/airflow/models/taskinstance.py", line 1312, in _execute_task
    result = task_copy.execute(context=context)
  File "/home/airflow/.local/lib/python3.8/site-packages/airflow/operators/python.py", line 150, in execute
    return_value = self.execute_callable()
  File "/home/airflow/.local/lib/python3.8/site-packages/airflow/operators/python.py", line 161, in execute_callable
    return self.python_callable(*self.op_args, **self.op_kwargs)
  File "/opt/airflow/dags/main_dag.py", line 316, in create_tables
    graph_table = data[["title", "parents", "siblings", "children"]]
  File "/home/airflow/.local/lib/python3.8/site-packages/pandas/core/frame.py", line 3461, in __getitem__
    indexer = self.loc._get_listlike_indexer(key, axis=1)[1]
  File "/home/airflow/.local/lib/python3.8/site-packages/pandas/core/indexing.py", line 1314, in _get_listlike_indexer
    self._validate_read_indexer(keyarr, indexer, axis)
  File "/home/airflow/.local/lib/python3.8/site-packages/pandas/core/indexing.py", line 1377, in _validate_read_indexer
    raise KeyError(f"{not_found} not in index")
KeyError: "['parents'] not in index"
[2021-12-31 10:16:05,431] {taskinstance.py:1505} INFO - Marking task as UP_FOR_RETRY. dag_id=main_dag, task_id=create_tables, execution_date=20211230T101115, start_date=20211231T101604, end_date=20211231T101605
[2021-12-31 10:16:05,503] {local_task_job.py:151} INFO - Task exited with return code 1
